{
  "cells": [
    {
      "cell_type": "markdown",
      "metadata": {},
      "source": "<|user|>\n\n\u91cd\u5e86\u5564\u91522024\u5e74Q1\u51c0\u5229\u540c\u6bd4\u589e\u957f\u591a\u5c11\uff1f"
    },
    {
      "cell_type": "markdown",
      "metadata": {},
      "source": "<|assistant|>\n\nIt seems that there was an error while attempting to read the Excel file. This might be due to the format of the file. I will need to specify the engine for reading the Excel file in order to proceed. Let me fix that and read the file again."
    },
    {
      "cell_type": "code",
      "execution_count": null,
      "metadata": {},
      "outputs": [
        {
          "name": "stdout",
          "text": [
            "---------------------------------------------------------------------------\nValueError                                Traceback (most recent call last)\nCell In[1], line 5\n      3 # Load the data from the uploaded file\n      4 file_path = \\"
          ],
          "output_type": "stream"
        }
      ],
      "source": [
        "import pandas as pd\r\n\r\n# Load the data from the uploaded file\r\nfile_path = '/mnt/data/assistant-KvZWOzaBuCpleyPW7AIndZnY'\r\ncq_beer_data = pd.read_excel(file_path)\r\n\r\n# Display the first few rows of the dataframe\r\ncq_beer_data.head()"
      ]
    },
    {
      "cell_type": "markdown",
      "metadata": {},
      "source": "<|assistant|>\n\nIt seems there was an issue with the Excel file format, and it might not be a valid zip file. Let's check the file and its format before proceeding with reading it."
    },
    {
      "cell_type": "code",
      "execution_count": null,
      "metadata": {},
      "outputs": [
        {
          "name": "stdout",
          "text": [
            "---------------------------------------------------------------------------\nBadZipFile                                Traceback (most recent call last)\nCell In[2], line 2\n      1 # Specify the engine as openpyxl and read the Excel file again\n----> 2 cq_beer_data = pd.read_excel(file_path, engine=\\"
          ],
          "output_type": "stream"
        }
      ],
      "source": [
        "# Specify the engine as openpyxl and read the Excel file again\r\ncq_beer_data = pd.read_excel(file_path, engine='openpyxl')\r\n\r\n# Display the first few rows of the dataframe\r\ncq_beer_data.head()"
      ]
    },
    {
      "cell_type": "markdown",
      "metadata": {},
      "source": "<|assistant|>\n\nIt appears that the required module for determining the file type is not available in this environment. Let me attempt to read the file using a different approach."
    },
    {
      "cell_type": "code",
      "execution_count": null,
      "metadata": {},
      "outputs": [
        {
          "name": "stdout",
          "text": [
            "---------------------------------------------------------------------------\nModuleNotFoundError                       Traceback (most recent call last)\nCell In[3], line 2\n      1 # Check the file to see if it's a valid Excel file\n----> 2 import magic\n      4 file_type = magic.Magic(mime=True)\n      5 file_mime_type = file_type.from_file(file_path)\n\nModuleNotFoundError: No module named 'magic'\n"
          ],
          "output_type": "stream"
        }
      ],
      "source": [
        "# Check the file to see if it's a valid Excel file\r\nimport magic\r\n\r\nfile_type = magic.Magic(mime=True)\r\nfile_mime_type = file_type.from_file(file_path)\r\nfile_mime_type"
      ]
    },
    {
      "cell_type": "markdown",
      "metadata": {},
      "source": "<|assistant|>\n\nIt looks like there was an error while trying to read the file using the UTF-8 encoding. This might suggest that the file is not encoded in UTF-8. Let's try to read the file with a different encoding to see if that helps us understand its format."
    },
    {
      "cell_type": "code",
      "execution_count": null,
      "metadata": {},
      "outputs": [
        {
          "name": "stdout",
          "text": [
            "---------------------------------------------------------------------------\nUnicodeDecodeError                        Traceback (most recent call last)\nCell In[4], line 3\n      1 # Let's try to read the first few lines of the file to understand its format\n      2 with open(file_path, 'r', encoding='utf-8') as file:\n----> 3     first_10_lines = ''.join([next(file) for _ in range(10)])\n      4     first_10_lines\n\nCell In[4], line 3, in <listcomp>(.0)\n      1 # Let's try to read the first few lines of the file to understand its format\n      2 with open(file_path, 'r', encoding='utf-8') as file:\n----> 3     first_10_lines = ''.join([next(file) for _ in range(10)])\n      4     first_10_lines\n\nFile /usr/lib/python3.8/codecs.py:322, in BufferedIncrementalDecoder.decode(self, input, final)\n    319 def decode(self, input, final=False):\n    320     # decode input (taking the buffer into account)\n    321     data = self.buffer + input\n--> 322     (result, consumed) = self._buffer_decode(data, self.errors, final)\n    323     # keep undecoded input until the next call\n    324     self.buffer = data[consumed:]\n\nUnicodeDecodeError: 'utf-8' codec can't decode byte 0xc4 in position 10: invalid continuation byte\n"
          ],
          "output_type": "stream"
        }
      ],
      "source": [
        "# Let's try to read the first few lines of the file to understand its format\r\nwith open(file_path, 'r', encoding='utf-8') as file:\r\n    first_10_lines = ''.join([next(file) for _ in range(10)])\r\n    first_10_lines"
      ]
    }
  ],
  "metadata": {
    "kernelspec": {
      "display_name": "Python 3",
      "language": "python",
      "name": "python3"
    },
    "language_info": {
      "codemirror_mode": {
        "name": "ipython",
        "version": 3
      },
      "file_extension": ".py",
      "mimetype": "text/x-python",
      "name": "python",
      "nbconvert_exporter": "python",
      "pygments_lexer": "ipython3",
      "version": "3.7.11"
    }
  },
  "nbformat": 4,
  "nbformat_minor": 5
}